Workbook

Sheet Order intake 2024
B1: PT. EXION SOLUSI REKAYASA INDONESIA
B2: YTD Order Booking
B3: Customer Name | C3: Currency | D3: Order Intake (PO Amount excluding tax ) | E3: Order Intake (PO Amount including 11% tax ) | F3: Order Date | G3: CUSTOMER PO | H3: Billed Orders (amount excluding tax ) | I3: Billed Orders (including 11% tax ) | J3: Invoice date | K3: Invoice Reference | L3: Exion Asia Job Number | M3: External Document No. | N3: Vendor Name | O3: Country | P3: Job Status | Q3: EDD
A4: 1 | B4: PT MULTIMAS NABATI ASAHAN | C4: IDR | D4: 45038703 | E4: 49992960 | F4: 45567 | G4: 1220279773 | H4: 45038703 | I4: 49992960 | J4: 45577 | K4: 002.XII.24 | L4: JN79240211 | M4: PO-PTEA-1024-0002 | N4: SPX | O4: CHINA | P4: Closed (Billed)
A5: 2 | B5: CV MUSIKA SADAWIRA BUANA | C5: IDR | D5: 5160000 | E5: 5727600 | F5: 45586 | G5: 001/MSB/IX/2024 | H5: 5160000 | I5: 5727600 | J5: 24/10/2024 | K5: 001.X.24 | L5: JN79240209 | M5: PO-PTEA-1024-0001 | N5: WIKA | O5: SINGAPORE | P5: Closed (Billed)
A6: 3 | B6: PT BEKASI POWER | C6: IDR | D6: 9897324.2 | E6: 10986030 | F6: 45593 | G6: 19716 | L6: JN79240225 | M6: PO-PTEA-1024-0003 | N6: ALPHA POMPE | O6: ITALY | P6: Open
A7: 4 | B7: PT BEKASI POWER | C7: IDR | D7: 15640425 | E7: 17360872 | F7: 45593 | G7: 19715 | L7: JN79240226 | M7: PO-PTEA-1024-0004 | N7: ALPHA POMPE | O7: ITALY | P7: Open
A8: 5 | B8: PT BEKASI POWER | C8: IDR | D8: 31840000 | E8: 35342400 | F8: 45600 | G8: 19739 | L8: JN79240238 | M8: PO-PTEA-1124-0005 | N8: EMERSON | O8: SINGAPORE | P8: Open
A9: 6 | B9: PT SWTS | C9: IDR | D9: 75871622 | E9: 84217500 | F9: 45621 | G9: P.GA .05 02 | H9: 75871622 | I9: 84217500 | J9: 25/11/2024 | K9: 001.XI.24 | L9: NA | M9: PO-PTEA-1124-0006 | N9: PT VISITEK | O9: INDONESIA | P9: Closed (Billed)
A10: 7 | B10: PT. ARTAM BORNEO AUTOMATIKA | C10: IDR | D10: 59000000 | E10: 65490000 | F10: 45629 | G10: 0302R1C38 | H10: 59000000 | I10: 65490000 | J10: 45577 | K10: 001.XII.24 | L10: NA | M10: PO-PTEA-1224-0007 | N10: A Syifa Firli Aisyah | O10: INDONESIA | P10: Closed (Billed)
E11: 0 | I11: 0
E12: 0 | I12: 0
E13: 0 | I13: 0
E14: 0 | I14: 0
E15: 0 | I15: 0
E16: 0 | I16: 0
E17: 0 | I17: 0
E18: 0 | I18: 0
E19: 0 | I19: 0
E20: 0 | I20: 0
E21: 0 | I21: 0
E22: 0 | I22: 0
... E25: 0 | I25: 0
C33: Month (2024) | D33: Order Intake (PO Amount excluding tax ) | E33: Order Intake (PO Amount including 11% tax ) | G33: Status | H33: Sum of Billed Orders (amount excluding tax ) | I33: Sum of Billed Orders (including 11% tax )
C34: Oct | D34: 75736452 | E34: 84067462 | G34: Closed (Billed) | H34: 1.8507032e+08 | I34: 2.0542806e+08
C35: Nov | D35: 1.0771162e+08 | E35: 1.195599e+08 | G35: Open | H35: 57377749 | I35: 63689302
C36: Dec | D36: 59000000 | E36: 65490000 | G36: (blank) | I36: 0
C37: Grand total (IDR) | D37: 2.4244807e+08 | E37: 2.6911736e+08 | G37: Grand Total | H37: 2.4244807e+08 | I37: 2.6911736e+08
C40: Grand total (SGD) | D40: 19395.846 | E40: 21529.389

Sheet May 2025
B1: PT. EXION SOLUSI REKAYASA INDONESIA
B2: YTD Order Booking
B3: Customer Name | D3: Currency | E3: Order Intake (PO Amount excluding tax ) | F3: Order Intake (PO Amount including 11% tax ) | G3: Order Date | H3: CUSTOMER PO | I3: Billed Orders (amount excluding tax ) | J3: Billed Orders (including 11% tax ) | K3: Invoice date | L3: Invoice Reference | M3: Exion Asia Job Number | N3: External Document No. | O3: Vendor Name | P3: Country | Q3: Job Status | R3: EDD
A4: 1 | B4: PT BEKASI POWER | D4: IDR | E4: - | F4: - | G4: 45593 | H4: 19716 | I4: 9897324.2 | J4: 10986030 | K4: 45666 | L4: 002.I.25 | M4: JN79240225 | N4: PO-PTEA-1024-0003 | O4: ALPHA POMPE | P4: ITALY | Q4: Closed (Billed)
A5: 2 | B5: PT BEKASI POWER | D5: IDR | E5: - | F5: - | G5: 45593 | H5: 19715 | I5: 15640425 | J5: 17360872 | K5: 45666 | L5: 001.I.25 | M5: JN79240226 | N5: PO-PTEA-1024-0004 | O5: ALPHA POMPE | P5: ITALY | Q5: Closed (Billed)
A6: 3 | B6: PT BEKASI POWER | D6: IDR | E6: - | F6: - | G6: 45600 | H6: 19739 | I6: 31840000 | J6: 35342400 | K6: 45666 | L6: 003.I.25 | M6: JN79240238 | N6: PO-PTEA-1124-0005 | O6: EMERSON | P6: SINGAPORE | Q6: Closed (Billed)
A7: 4 | B7: PLN NUSANTARA POWER | D7: IDR | E7: 32760000 | F7: 36363600 | G7: 45667 | I7: 32760000 | J7: 36363600 | K7: 45708 | L7: 001.II.25 | M7: NA | N7: NA | O7: NA | P7: ID | Q7: Closed (Billed)
A8: 5 | B8: PLN NUSANTARA POWER | D8: IDR | E8: 42900000 | F8: 47619000 | G8: 45667 | I8: 42900000 | J8: 47619000 | K8: 45708 | L8: 002.II.25 | M8: NA | N8: NA | O8: NA | P8: ID | Q8: Closed (Billed)
A9: 6 | B9: PLN NUSANTARA POWER | D9: IDR | E9: 35458000 | F9: 39358380 | G9: 45667 | I9: 35458000 | J9: 39358380 | K9: 45708 | L9: 003.II.25 | M9: NA | N9: NA | O9: NA | P9: ID | Q9: Closed (Billed)
A10: 7 | B10: PT PLN NPS Anggrek | D10: IDR | E10: 21738375 | F10: 24129596 | G10: 45684 | I10: 21738375 | J10: 24129596 | K10: 45755 | L10: 001.IV.25 | M10: NA | N10: NA | O10: NA | P10: ID | Q10: Closed (Billed)
A11: 8 | B11: PT BEKASI POWER | D11: IDR | E11: 63680000 | F11: 70684800 | G11: 45685 | I11: 63680000 | J11: 70684800 | K11: 45812 | L11: 001.VI.25 | M11: JN79250021 | N11: PO-PTEA-0225-0001 | O11: EMERSON | P11: SG | Q11: Closed (Billed) | R11: 45762
A12: 9 | B12: PT PLN NPS Anggrek | D12: IDR | E12: 15905500 | F12: 17655105 | G12: 45701 | I12: 15905500 | J12: 17655105 | M12: NA | N12: NA | O12: NA | P12: NA | Q12: Open
A13: 10 | B13: PT. Pacrim Nusantara Lestari Foods | D13: IDR | E13: 37631444 | F13: 41770903 | G13: 45709 | I13: 37631444 | J13: 41770903 | K13: 45723 | L13: 001.III.25 | M13: JN79250023 | N13: PO-PTEA-0225-0002 | O13: ENCORD SDN BHD | P13: MY | Q13: Closed (Billed) | R13: 45719
A14: 11 | B14: PT. PETROKOPINDO CIPTA SELARAS | D14: IDR | E14: 998000000 | F14: 1107780000 | G14: 45705 | I14: 998000000 | J14: 1107780000 | M14: NA | N14: PO-PTEA-0225-0003 | O14: PT SWTS INDONESIA | P14: ID | Q14: Open | R14: 45720
A15: 12 | B15: PT PLN NPS Anggrek | D15: IDR | E15: 10686000 | F15: 11861460 | G15: 45716 | I15: 10686000 | J15: 11861460 | M15: NA | N15: NA | O15: NA | P15: NA | Q15: Open
A16: 13 | B16: PT PLN NPS Anggrek | D16: IDR | E16: 13837200 | F16: 15359292 | G16: 45716 | I16: 13837200 | J16: 15359292 | M16: NA | N16: NA | O16: NA | P16: NA | Q16: Open
A17: 14 | B17: PT. Pacrim Nusantara Lestari Foods | D17: IDR | E17: 11564500 | F17: 12836595 | G17: 45720 | I17: 11564500 | J17: 12836595 | K17: 45737 | L17: 003.III.25 | M17: JN79250029 | N17: PO-PTEA-0325-0004 | O17: ENCORD SDN BHD | P17: MY | Q17: Closed (Billed) | R17: 45733
A18: 15 | B18: PT PLN Nusantara Power Service | D18: IDR | E18: 45000000 | F18: 49950000 | G18: 45723 | I18: 45000000 | J18: 49950000 | M18: NA | N18: NA | O18: NA | P18: NA | Q18: Open
A19: 16 | B19: PT PLN NPS PLTU Amurang | D19: IDR | E19: 1410000 | F19: 1565100 | G19: 45740 | I19: 1410000 | J19: 1565100 | M19: NA | N19: NA | O19: NA | P19: NA | Q19: Open
A20: 17 | B20: PT PLN NPS PLTU Amurang | D20: IDR | E20: 41750000 | F20: 46342500 | G20: 45757 | I20: 41750000 | J20: 46342500 | M20: NA | N20: NA | O20: NA | P20: NA | Q20: Open
A21: 18 | B21: PLN NP UP Tanjung Awar-awar, PT | D21: IDR | E21: 211000000 | F21: 2.3421e+08 | G21: 45762 | I21: 211000000 | J21: 2.3421e+08 | M21: JN79250064 | N21: PO-PTEA-0525-0006 | O21: SPX FLOW | P21: CHINA | Q21: Open | R21: 45852
A22: 19 | B22: PLN NP UP Tanjung Awar-awar, PT | D22: IDR | E22: 229000000 | F22: 2.5419e+08 | G22: 45762 | I22: 229000000 | J22: 2.5419e+08 | M22: JN79250063 | N22: PO-PTEA-0525-0007 | O22: SPX FLOW | P22: CHINA | Q22: Open | R22: 45855
A23: 20 | B23: PT Elmoz Geo Solusi | D23: IDR | E23: 70468000 | F23: 78219480 | G23: 45763 | I23: 70468000 | J23: 78219480 | M23: JN79250053 | N23: PO-PTEA-0425-0005 | O23: ENCORD SDN BHD | P23: MY | Q23: Open | R23: 45832
A24: 21 | B24: PT PLN NPS PLTU Amurang | D24: IDR | E24: 6850400 | F24: 7603944 | G24: 45783 | I24: 6850400 | J24: 7603944 | M24: NA | N24: NA | O24: NA | P24: NA | Q24: Open
A25: 22 | B25: PT PLN NPS PLTU Amurang | D25: IDR | E25: 44000000 | F25: 48840000 | G25: 45804 | I25: 44000000 | J25: 48840000 | M25: NA | N25: NA | O25: NA | P25: NA | Q25: Open
B26: YTD order intake | E26: =SUM(E4:E25) -> 1933639419
B27: Backlog | E27: =I38 -> 1687907100
D36: Month (2025) | E36: Order Intake (PO Amount excluding tax ) | F36: Order Intake (PO Amount including 11% tax ) | H36: Status | I36: Sum of Billed Orders (amount excluding tax ) | J36: Sum of Billed Orders (including 11% tax )
D37: January | E37: 196536375 | F37: 2.1815538e+08 | H37: Closed (Billed) | I37: 3.0311007e+08 | J37: 3.3645218e+08
D38: Feb | E38: 1076060144 | F38: 1.1944268e+09 | H38: Open | I38: 1687907100 | J38: 1873576881
D39: Mar | E39: 57974500 | F39: 64351695 | H39: Grand Total | I39: 1.9910172e+09 | J39: 2.2100291e+09
D40: Apr | E40: 552218000 | F40: 6.1296198e+08
D41: May | E41: 50850400 | F41: 56443944
D42: Jun
D43: Jul
D44: Aug
D45: Sep
D46: Oct
D47: Nov
D48: Dec
...

Sheet Jun 2025
A1: PT. EXION SOLUSI REKAYASA INDONESIA
A2: YTD Order Booking
A3: Customer Name | B3: Currency | C3: Order Intake (PO Amount excluding tax ) | D3: Order Intake (PO Amount including 11% tax ) | E3: Order Date | F3: CUSTOMER PO | G3: Billed Orders (amount excluding tax ) | H3: Billed Orders (including 11% tax ) | I3: Invoice date | J3: Invoice Reference | K3: Exion Asia Job Number | L3: External Document No. | M3: Vendor Name | N3: Country | O3: Job Status | P3: EDD
A4: PT BEKASI POWER | B4: IDR | C4: 9897324.2 | D4: 10986030 | E4: 45593 | F4: 19716 | G4: =IF($O4 = "Closed (Billed)", $C4, "") -> 9897324.2 | H4: =IF($O4 = "Closed (Billed)", $D4, " ") -> 10986030 | I4: 45666 | J4: 002.I.25 | K4: JN79240225 | L4: PO-PTEA-1024-0003 | M4: ALPHA POMPE | N4: ITALY | O4: Closed (Billed)
A5: PT BEKASI POWER | B5: IDR | C5: 15640425 | D5: 17360872 | E5: 45593 | F5: 19715 | G5: =IF($O5 = "Closed (Billed)", $C5, "") -> 15640425 | H5: =IF($O5 = "Closed (Billed)", $D5, " ") -> 17360872 | I5: 45666 | J5: 001.I.25 | K5: JN79240226 | L5: PO-PTEA-1024-0004 | M5: ALPHA POMPE | N5: ITALY | O5: Closed (Billed)
A6: PT BEKASI POWER | B6: IDR | C6: 31840000 | D6: 35342400 | E6: 45600 | F6: 19739 | G6: =IF($O6 = "Closed (Billed)", $C6, "") -> 31840000 | H6: =IF($O6 = "Closed (Billed)", $D6, " ") -> 35342400 | I6: 45666 | J6: 003.I.25 | K6: JN79240238 | L6: PO-PTEA-1124-0005 | M6: EMERSON | N6: SINGAPORE | O6: Closed (Billed)
A7: PLN NUSANTARA POWER | B7: IDR | C7: 32760000 | D7: 36363600 | E7: 45667 | G7: =IF($O7 = "Closed (Billed)", $C7, "") -> 32760000 | H7: =IF($O7 = "Closed (Billed)", $D7, " ") -> 36363600 | I7: 45708 | J7: 001.II.25 | K7: NA | L7: PO/EXSRI/1224/0001 | M7: Indra Kusuma | N7: ID | O7: Closed (Billed)
A8: PLN NUSANTARA POWER | B8: IDR | C8: 42900000 | D8: 47619000 | E8: 45667 | G8: =IF($O8 = "Closed (Billed)", $C8, "") -> 42900000 | H8: =IF($O8 = "Closed (Billed)", $D8, " ") -> 47619000 | I8: 45708 | J8: 002.II.25 | K8: NA | L8: PO/EXSRI/1224/0002 | M8: Indra Kusuma | N8: ID | O8: Closed (Billed)
A9: PLN NUSANTARA POWER | B9: IDR | C9: 35458000 | D9: 39358380 | E9: 45667 | G9: =IF($O9 = "Closed (Billed)", $C9, "") -> 35458000 | H9: =IF($O9 = "Closed (Billed)", $D9, " ") -> 39358380 | I9: 45708 | J9: 003.II.25 | K9: NA | L9: PO/EXSRI/1224/0003 | M9: Indra Kusuma | N9: ID | O9: Closed (Billed)
A10: PT PLN NPS Anggrek | B10: IDR | C10: 21738375 | D10: 24129596 | E10: 45684 | G10: =IF($O10 = "Closed (Billed)", $C10, "") -> 21738375 | H10: =IF($O10 = "Closed (Billed)", $D10, " ") -> 24129596 | I10: 45755 | J10: 001.IV.25 | K10: NA | L10: PO/EXSRI/0225/0001 | M10: Muhammad Rifai | N10: ID | O10: Closed (Billed)
A11: PT BEKASI POWER | B11: IDR | C11: 63680000 | D11: 70684800 | E11: 45685 | G11: =IF($O11 = "Closed (Billed)", $C11, "") -> 63680000 | H11: =IF($O11 = "Closed (Billed)", $D11, " ") -> 70684800 | I11: 45812 | J11: 001.VI.25 | K11: JN79250021 | L11: PO-PTEA-0225-0001 | M11: EMERSON | N11: SG | O11: Closed (Billed) | P11: 45762
A12: PT PLN NPS Anggrek | B12: IDR | C12: 15905500 | D12: 17655105 | E12: 45701 | F12: PO-1245 | G12: =IF($O12 = "Closed (Billed)", $C12, "") -> 15905500 | H12: =IF($O12 = "Closed (Billed)", $D12, " ") -> 17655105 | I12: 45755 | J12: 002.IV.25 | K12: NA | L12: PO/EXSRI/0225/0002 | M12: Muhammad Rifai | N12: NA | O12: Closed (Billed)
A13: PT. Pacrim Nusantara Lestari Foods | B13: IDR | C13: 37631444 | D13: 41770903 | E13: 45709 | G13: =IF($O13 = "Closed (Billed)", $C13, "") -> 37631444 | H13: =IF($O13 = "Closed (Billed)", $D13, " ") -> 41770903 | I13: 45723 | J13: 001.III.25 | K13: JN79250023 | L13: PO-PTEA-0225-0002 | M13: ENCORD SDN BHD | N13: MY | O13: Closed (Billed) | P13: 45719
A14: PT. PETROKOPINDO CIPTA SELARAS | B14: IDR | C14: 998000000 | D14: 1107780000 | E14: 45705 | G14: =IF($O14 = "Closed (Billed)", $C14, "") | H14: =IF($O14 = "Closed (Billed)", $D14, " ") | K14: NA | L14: PO-PTEA-0225-0003 | M14: PT SWTS INDONESIA | N14: ID | O14: Open | P14: 45720
A15: PT PLN NPS Anggrek | B15: IDR | C15: 10686000 | D15: 11861460 | E15: 45716 | G15: =IF($O15 = "Closed (Billed)", $C15, "") | H15: =IF($O15 = "Closed (Billed)", $D15, " ") | K15: NA | L15: PO/EXSRI/0325/0003 | M15: Muhammad Rifai | N15: NA | O15: Open
A16: PT PLN NPS Anggrek | B16: IDR | C16: 13837200 | D16: 15359292 | E16: 45716 | G16: =IF($O16 = "Closed (Billed)", $C16, "") | H16: =IF($O16 = "Closed (Billed)", $D16, " ") | K16: NA | L16: PO/EXSRI/0325/0004 | M16: Muhammad Rifai | N16: NA | O16: Open
A17: PT. Pacrim Nusantara Lestari Foods | B17: IDR | C17: 11564500 | D17: 12836595 | E17: 45720 | G17: =IF($O17 = "Closed (Billed)", $C17, "") -> 11564500 | H17: =IF($O17 = "Closed (Billed)", $D17, " ") -> 12836595 | I17: 45737 | J17: 003.III.25 | K17: JN79250029 | L17: PO-PTEA-0325-0004 | M17: ENCORD SDN BHD | N17: MY | O17: Closed (Billed) | P17: 45733
A18: PT PLN Nusantara Power Service | B18: IDR | C18: 44375000 | D18: 49256250 | E18: 45723 | F18: POM012 | G18: =IF($O18 = "Closed (Billed)", $C18, "") -> 44375000 | H18: =IF($O18 = "Closed (Billed)", $D18, " ") -> 49256250 | I18: 45735 | J18: 002.III.25 | K18: NA | L18: PO/EXSRI/0325/0005 | M18: PT Kairos Mulia Abadi | N18: NA | O18: Closed (Billed)
A19: PT PLN NPS PLTU Amurang | B19: IDR | C19: 1410000 | D19: 1565100 | E19: 45740 | G19: =IF($O19 = "Closed (Billed)", $C19, "") | H19: =IF($O19 = "Closed (Billed)", $D19, " ") | K19: NA | L19: PO/EXSRI/0325/0006 | M19: NA | N19: NA | O19: Open
A20: PT PLN NPS PLTU Amurang | B20: IDR | C20: 41750000 | D20: 46342500 | E20: 45757 | G20: =IF($O20 = "Closed (Billed)", $C20, "") | H20: =IF($O20 = "Closed (Billed)", $D20, " ") | K20: NA | L20: PO/EXSRI/0425/0007 | M20: NA | N20: NA | O20: Open
A21: PLN NP UP Tanjung Awar-awar, PT | B21: IDR | C21: 211000000 | D21: 2.3421e+08 | E21: 45762 | G21: =IF($O21 = "Closed (Billed)", $C21, "") | H21: =IF($O21 = "Closed (Billed)", $D21, " ") | K21: JN79250064 | L21: PO-PTEA-0525-0006 | M21: SPX FLOW | N21: CHINA | O21: Open | P21: 45852
A22: PLN NP UP Tanjung Awar-awar, PT | B22: IDR | C22: 229000000 | D22: 2.5419e+08 | E22: 45762 | G22: =IF($O22 = "Closed (Billed)", $C22, "") | H22: =IF($O22 = "Closed (Billed)", $D22, " ") | K22: JN79250063 | L22: PO-PTEA-0525-0007 | M22: SPX FLOW | N22: CHINA | O22: Open | P22: 45855
A23: PT Elmoz Geo Solusi | B23: IDR | C23: 70468000 | D23: 78219480 | E23: 45763 | G23: =IF($O23 = "Closed (Billed)", $C23, "") | H23: =IF($O23 = "Closed (Billed)", $D23, " ") | K23: JN79250053 | L23: PO-PTEA-0425-0005 | M23: ENCORD SDN BHD | N23: MY | O23: Open | P23: 45832
A24: PT PLN NPS PLTU Amurang | B24: IDR | C24: 6850400 | D24: 7603944 | E24: 45783 | G24: =IF($O24 = "Closed (Billed)", $C24, "") | H24: =IF($O24 = "Closed (Billed)", $D24, " ") | K24: NA | L24: PO/EXSRI/0425/0008 | M24: NA | N24: NA | O24: Open
A25: PT PLN NPS PLTU Amurang | B25: IDR | C25: 44000000 | D25: 48840000 | E25: 45804 | G25: =IF($O25 = "Closed (Billed)", $C25, "") | H25: =IF($O25 = "Closed (Billed)", $D25, " ") | K25: NA | L25: NA | M25: NA | N25: NA | O25: Open
A26: PLN NP UP Tanjung Awar-awar, PT | B26: IDR | C26: 211000000 | D26: 2.3421e+08 | F26: PENDING OFFICIAL PO | K26: JN79250077 | L26: PO-PTEA-0625-0010 | M26: SPX FLOW | N26: CHINA | O26: Open
A32: YTD order intake | C32: =SUM(C4:C31) -> 2.2013922e+09 | D32: =SUM($D$4:$D$31) -> 2.4435453e+09
A33: Backlog 31 May | C33: 1687907100 | D33: 1.8735769e+09
A34: Backlog 30 Jun | C34: =G38 -> 1838001600 | D34: =H38 -> 2.0401818e+09
B36: Month (2025) | C36: Order Intake (PO Amount excluding tax ) | D36: Order Intake (PO Amount including 11% tax ) | F36: Status | G36: Sum of Billed Orders (amount excluding tax ) | H36: Sum of Billed Orders (including 11% tax )
B37: January | C37: 196536375 | D37: 2.1815538e+08 | F37: Closed (Billed) | G37: =SUM($G4:$G25) -> 3.6339057e+08 | H37: =SUM($H4:$H25) -> 4.0336353e+08
B38: Feb | C38: 1076060144 | D38: 1.1944268e+09 | F38: Open | G38: =$C$32 - $G$37 -> 1838001600 | H38: =$G$38*1.11 -> 2.0401818e+09
B39: Mar | C39: 57974500 | D39: 64351695 | F39: Grand Total | G39: 1.9910172e+09 | H39: 2.2100291e+09
B40: Apr | C40: 552218000 | D40: 6.1296198e+08
B41: May | C41: 50850400 | D41: 56443944
B42: Jun | C42: =C26 -> 211000000 | D42: =D26 -> 2.3421e+08
B43: Jul
B44: Aug
B45: Sep
B46: Oct
...

Sheet Order Book
A1: PT EXSRI | C1: MTD | G1: YTD
D2: Ex Rate
B3: No. | C3: IDR | D3: 8.69e-05 | E3: SGD | G3: =C3 -> IDR | H3: =E3 -> SGD
A4: Backlog @1 Aug 2024 | C4: 0 | E4: =$C4*$D$3 -> 0 | F4: Backlog @1 Aug 2024 | G4: =C4 -> 0 | H4: =E4 -> 0
A5: Order intake | B5: ='Order intake 2024'!A10 -> 7 | C5: ='Order intake 2024'!D37 -> 2.4244807e+08 | E5: =$C5*$D$3 -> 21068.738 | F5: Order intake | G5: =C5 -> 2.4244807e+08 | H5: =E5 -> 21068.738
A6: Sales | C6: 185070325 | E6: =$C6*$D$3 -> 16082.611 | F6: Sales | G6: =C6 -> 185070325 | H6: =E6 -> 16082.611
A7: Backlog @31 Dec 2024 | C7: =C4+C5-C6 -> 57377749 | E7: =E4+E5-E6 -> 4986.1264 | F7: Backlog @31 Dec 2024 | G7: =C7 -> 57377749 | H7: =E7 -> 4986.1264
D9: 9e-05
A10: Backlog @1 Jan 2025 | C10: =C7 -> 57377749 | E10: =$C10*$D$9 -> 5163.9974 | F10: Backlog @1 Jan 2025 | G10: =C10 -> 57377749 | H10: =E10 -> 5163.9974
A11: Order intake | B11: ='May 2025'!A25-'May 2025'!A6 -> 19 | C11: ='May 2025'!E26 -> 1933639419 | E11: =$C11*$D$9 -> 174027.55 | F11: Order intake | G11: =C11 -> 1933639419 | H11: =E11 -> 174027.55 | I11: =H11+H5 -> 195096.29
A12: Sales | C12: 3.0311007e+08 | E12: =$C12*$D$9 -> 27279.906 | F12: Sales | G12: =C12 -> 3.0311007e+08 | H12: =E12 -> 27279.906 | I12: =H12+H6 -> 43362.517
A13: Backlog @31 May 2025 | C13: =C10+C11-C12 -> 1.6879071e+09 | E13: =E10+E11-E12 -> 151911.64 | F13: Backlog @31 May 2025 | G13: =C13 -> 1.6879071e+09 | H13: =H10+H11-H12 -> 151911.64
C14: ='May 2025'!E27 -> 1687907100
C15: =C13-C14 -> -0.38000011
A17: Backlog @1 Jun 2025 | C17: =C13 -> 1.6879071e+09 | E17: =E13 -> 151911.64 | F17: =F10 -> Backlog @1 Jan 2025 | G17: =G10 -> 57377749 | H17: =H10 -> 5163.9974
A18: Order intake | F18: =A18 -> Order intake | G18: =G11+C18 -> 1933639419 | H18: =H11+E18 -> 174027.55
A19: Sales | F19: =A19 -> Sales | G19: =G12+C19 -> 3.0311007e+08 | H19: =H12+E19 -> 27279.906
A20: Backlog @30 Jun 2025 | C20: =C17+C18-C19 -> 1.6879071e+09 | E20: =E17+E18-E19 -> 151911.64 | F20: =A20 -> Backlog @30 Jun 2025 | G20: =G17+G18-G19 -> 1.6879071e+09 | H20: =H17+H18-H19 -> 151911.64

Sheet PIVOT-CUSTOMER
A2: IDR | J2: =SUBTOTAL(9,J5:J10) -> 1.3136978e+08
A3: Sum of Billed Orders | B3: Column Labels | H3: Vendor Name
A4: Customer Name | B4: 45658 | C4: 45717 | D4: 45748 | E4: 45809 | F4: 45839 | G4: Grand Total | J4: Margin (YTD JUL2025)
A5: PLN NUSANTARA POWER | B5: 111118000 | G5: 111118000 | H5: Indra Kusuma | J5: 25625000
A6: PT BEKASI POWER | B6: 57377749 | E6: 63680000 | G6: 121057749 | H6: ALPHA POMPE | I6: EMERSON | J6: 40987862
A7: PT PLN NPS Anggrek | D7: 37643875 | F7: 24523200 | G7: 62167075 | H7: Muhammad Rifai | J7: 14271648
A8: PT PLN NPS PLTU Amurang | F8: 56860800 | G8: 56860800 | J8: 28569514
A9: PT PLN Nusantara Power Service | C9: 44375000 | G9: 44375000 | J9: 5875000
A10: PT. Pacrim Nusantara Lestari Foods | C10: 49195944 | G10: 49195944 | J10: 16040754
A11: Grand Total | B11: 168495749 | C11: 93570944 | D11: 37643875 | E11: 63680000 | F11: 81384000 | G11: 444774568
A13: 8e-05
A15: SGD
A16: Customer Name | B16: 45658 | C16: 45717 | D16: 45748 | E16: 45809 | F16: 45839 | G16: Grand Total
A17: PLN NUSANTARA POWER | B17: =B5*$A$13 -> 8889.44 | C17: =C5*$A$13 -> 0 | D17: =D5*$A$13 -> 0 | E17: =E5*$A$13 -> 0 | F17: =F5*$A$13 -> 0 | G17: =G5*$A$13 -> 8889.44 | H17: =G17/$G$23 -> 0.24982993 | I17: =SUM(H17:H19) -> 0.6617798
A18: PT BEKASI POWER | B18: =B6*$A$13 -> 4590.2199 | C18: =C6*$A$13 -> 0 | D18: =D6*$A$13 -> 0 | E18: =E6*$A$13 -> 5094.4 | F18: =F6*$A$13 -> 0 | G18: =G6*$A$13 -> 9684.6199 | H18: =G18/$G$23 -> 0.27217777
A19: PT PLN NPS Anggrek | B19: =B7*$A$13 -> 0 | C19: =C7*$A$13 -> 0 | D19: =D7*$A$13 -> 3011.51 | E19: =E7*$A$13 -> 0 | F19: =F7*$A$13 -> 1961.856 | G19: =G7*$A$13 -> 4973.366 | H19: =G19/$G$23 -> 0.1397721
A20: PT PLN NPS PLTU Amurang | B20: =B8*$A$13 -> 0 | C20: =C8*$A$13 -> 0 | D20: =D8*$A$13 -> 0 | E20: =E8*$A$13 -> 0 | F20: =F8*$A$13 -> 4548.864 | G20: =G8*$A$13 -> 4548.864 | H20: =G20/$G$23 -> 0.12784184
A21: PT PLN Nusantara Power Service | B21: =B9*$A$13 -> 0 | C21: =C9*$A$13 -> 3550 | D21: =D9*$A$13 -> 0 | E21: =E9*$A$13 -> 0 | F21: =F9*$A$13 -> 0 | G21: =G9*$A$13 -> 3550 | H21: =G21/$G$23 -> 0.099769643
A22: PT. Pacrim Nusantara Lestari Foods | B22: =B10*$A$13 -> 0 | C22: =C10*$A$13 -> 3935.6755 | D22: =D10*$A$13 -> 0 | E22: =E10*$A$13 -> 0 | F22: =F10*$A$13 -> 0 | G22: =G10*$A$13 -> 3935.6755 | H22: =G22/$G$23 -> 0.11060872
A23: Grand Total | B23: =B11*$A$13 -> 13479.66 | C23: =C11*$A$13 -> 7485.6755 | D23: =D11*$A$13 -> 3011.51 | E23: =E11*$A$13 -> 5094.4 | F23: =F11*$A$13 -> 6510.72 | G23: =G11*$A$13 -> 35581.965

Sheet Order Booking > Billing  2026
A1: PT. EXION SOLUSI REKAYASA INDONESIA | H1: FINANCE INDONESIA | Q1: FINANCE IND
A2: YTD Order Booking | C2: =SUBTOTAL(9,C4:C56) -> 2471815143 | D2: =SUBTOTAL(9,D4:D56) -> 2743714808 | I2: =SUBTOTAL(9,I4:I62) -> 1468301143 | J2: =SUBTOTAL(9,J4:J62) -> 1629814268 | V2: =SUBTOTAL(9,V4:V29) -> 1390858543 | W2: 2.2892806e+08
A3: Customer Name | B3: Currency | C3: Order Intake (PO Amount excluding tax ) | D3: Order Intake (PO Amount including 11% tax ) | E3: Order Date | F3: EDD (GOODS TO CUSTOMER) | G3: CUSTOMER PO | H3: QC Reporting Month | I3: Billed Orders (amount excluding tax ) | J3: Billed Orders (including 11% tax ) | K3: Invoice date | L3: Invoice Reference | M3: Exion Asia/ Valvewerkz Job Number | N3: External Document No. | O3: Vendor Name | P3: Country | Q3: Job Status | R3: PURCHASE VALUE | S3: CURRENCY | T3: VENDOR NAME | V3: Revenue (Net net amount) | W3: Margin (Net net amount) | X3: Categories | AB3: EXSRI JOB NUMBER
A4: PACRIM NUSANTARA LESTARI FOODS,PT | B4: IDR | C4: 216268594 | D4: =MROUND((C4*1.11),1) -> 240058139 | E4: 45945 | F4: 46082 | G4: 71004095 | H4: 46082 | I4: =IF($Q4 = "Closed (Billed)",$C4,"") -> 216268594 | J4: =IF($Q4 = "Closed (Billed)",$D4,"") -> 240058139 | K4: 46105 | L4: 005.III.26 | M4: JN01250002 | N4: PO-PTEA-1125-0027 | O4: VALVEWERKZ | P4: SG | Q4: Closed (Billed) | R4: 7870 | S4: USD | T4: VALVEWERKZ | V4: =I4 -> 216268594 | W4: 64240033 | X4: Spare Parts / equipment supply for existing plants | AB4: 2510010033 | AC4: =VLOOKUP(AB4,[1]Sheet3!B$2:C$78,2,0) -> 64240033 | AD4: =W4-AC4 -> 0
A5: PLN NUSANTARA POWER | B5: IDR | C5: 267200000 | D5: =MROUND((C5*1.11),1) -> 296592000 | E5: 45960 | F5: 46113 | G5: TAC715.SPK/612/UPTA/2025 | H5: 46174 | I5: =IF($Q5 = "Closed (Billed)",$C5,"") -> 267200000 | J5: =IF($Q5 = "Closed (Billed)",$D5,"") -> 296592000 | K5: 46183 | L5: 003.VI.26 | M5: JN79250178 | N5: PO-PTEA-1125-0033 | O5: SPX FLOW | P5: SG | Q5: Closed (Billed) | R5: 5972.76 | S5: USD | T5: EXION ASIA PTE LTD | V5: =I5 -> 267200000 | AB5: 2511010034 | AC5: =VLOOKUP(AB5,[1]Sheet3!B$2:C$78,2,0) -> -2.0133019e+08 | AD5: =W5-AC5 -> 2.0133019e+08
F6: 46113 | M6: NA | N6: PO-PTEA-0126-0004 | O6: XI'AN XINBEILANG | P6: CN | R6: 3736 | S6: USD | T6: XI'AN XINBEILANG | V6: =I6 -> 0 | AC6: =VLOOKUP(AB6,[1]Sheet3!B$2:C$78,2,0) -> #N/A
A7: PT. SINAR MAS AGRO RESOURCES AND TECHNOLOGY TBK. (SMART TBK.) | B7: IDR | C7: 81120000 | D7: =MROUND((C7*1.11),1) -> 90043200 | E7: 45968 | F7: 46023 | G7: 9900033981 | H7: 46023 | I7: =IF($Q7 = "Closed (Billed)",$C7,"") -> 81120000 | J7: =IF($Q7 = "Closed (Billed)",$D7,"") -> 90043200 | K7: 46030 | L7: 002.I.26 | M7: NA | N7: PO-PTEA-1125-0029 | O7: ENCORD SDN BHD | P7: MY | Q7: Closed (Billed) | V7: =I7 -> 81120000 | W7: 14251404 | X7: Spare Parts / equipment supply for existing plants | AB7: 2511010036 | AC7: =VLOOKUP(AB7,[1]Sheet3!B$2:C$78,2,0) -> 14251404 | AD7: =W7-AC7 -> 0
A8: Apical_PT.Sari Dumai Oleo | B8: IDR | C8: 14886000 | D8: =MROUND((C8*1.11),1) -> 16523460 | E8: 45972 | F8: 46113 | G8: 4500443666 | H8: 46174 | I8: =IF($Q8 = "Closed (Billed)",$C8,"") -> 14886000 | J8: =IF($Q8 = "Closed (Billed)",$D8,"") -> 16523460 | K8: 46178 | L8: 002.VI.26 | M8: NA | N8: PO-PTEA-1225-0035 | O8: HELS ENDUSTRIYEL | P8: TURKEY | Q8: Closed (Billed) | R8: 5435.23 | S8: USD | T8: HELS ENDUSTRIYEL | V8: =I8 -> 14886000 | AB8: 2511010035 | AC8: =VLOOKUP(AB8,[1]Sheet3!B$2:C$78,2,0) -> -14913022 | AD8: =W8-AC8 -> 14913022
A9: PT. OSA PUTRA ENGINEERING | B9: IDR | C9: 108274310 | D9: =MROUND((C9*1.11),1) -> 120184484 | E9: 45973 | F9: 46023 | G9: 2794/11/2025/MEI66 REVISI-1 | H9: 46023 | I9: =IF($Q9 = "Closed (Billed)",$C9,"") -> 108274310 | J9: =IF($Q9 = "Closed (Billed)",$D9,"") -> 120184484 | K9: 46029 | L9: 001.I.26 | M9: NA | N9: PO-PTEA-1125-0028 | O9: INGERSOLL RAND | P9: SG | Q9: Closed (Billed) | V9: =I9 -> 108274310 | W9: 32305920 | X9: Spare Parts / equipment supply for existing plants | AB9: 2511010037 | AC9: =VLOOKUP(AB9,[1]Sheet3!B$2:C$78,2,0) -> 32305920 | AD9: =W9-AC9 -> 0
A10: PT ENERGI UNGGUL PERSADA | B10: IDR | C10: 147957000 | D10: =MROUND((C10*1.11),1) -> 164232270 | E10: 45975 | F10: 46113 | G10: 1002034500 | H10: 46113 | I10: =IF($Q10 = "Closed (Billed)",$C10,"") -> 147957000 | J10: =IF($Q10 = "Closed (Billed)",$D10,"") -> 164232270 | K10: 46142 | L10: 006.IV.26 | M10: JN02250002 | N10: PO-PTEA-1125-0031 | O10: VALVEWERKZ | P10: SG | Q10: Closed (Billed) | R10: 10908 | S10: USD | T10: VALVEWERKZ | V10: =I10 -> 147957000 | W10: 43227941 | X10: Spare Parts / equipment supply for existing plants | AB10: 2511010041 | AC10: =VLOOKUP(AB10,[1]Sheet3!B$2:C$78,2,0) -> 43227941 | AD10: =W10-AC10 -> 0
A11: PT ENERGI UNGGUL PERSADA | B11: IDR | C11: 147957000 | D11: =MROUND((C11*1.11),1) -> 164232270 | E11: 45975 | F11: 46082 | G11: 1002034501 | H11: 46082 | I11: =IF($Q11 = "Closed (Billed)",$C11,"") -> 147957000 | J11: =IF($Q11 = "Closed (Billed)",$D11,"") -> 164232270 | K11: 46097 | L11: 002.III.26 | M11: JN02250002 | N11: PO-PTEA-1125-0031 | O11: VALVEWERKZ | P11: SG | Q11: Closed (Billed) | V11: =I11 -> 147957000 | W11: 43227942 | X11: Spare Parts / equipment supply for existing plants | AB11: 2511010038 | AC11: =VLOOKUP(AB11,[1]Sheet3!B$2:C$78,2,0) -> 43227942 | AD11: =W11-AC11 -> 0
A12: PT Amman Mineral Industri | B12: IDR | C12: 56813124 | D12: =MROUND((C12*1.11),1) -> 63062568 | E12: 45981 | F12: 46113 | G12: 3600003465 | H12: 46174 | I12: =IF($Q12 = "Closed (Billed)",$C12,"") -> 56813124 | J12: =IF($Q12 = "Closed (Billed)",$D12,"") -> 63062568 | K12: 46178 | L12: 001.VI.26 | M12: JN82250490 | N12: PO-PTEA-1225-0034 | O12: INTERVALVE POONAWALLA PVT. LTD. | P12: INDIA | Q12: Closed (Billed) | R12: 2205 | S12: USD | T12: EXION ASIA PTE LTD | V12: =I12 -> 56813124 | AB12: 2512010043 | AC12: =VLOOKUP(AB12,[1]Sheet3!B$2:C$78,2,0) -> -37732688 | AD12: =W12-AC12 -> 37732688
A13: PT EVONIK INDONESIA | B13: IDR | C13: 12815875 | D13: =MROUND((C13*1.11),1) -> 14225621 | E13: 45985 | F13: 46023 | G13: 4710193706-ID1/1120 | H13: 46023 | I13: =IF($Q13 = "Closed (Billed)",$C13,"") -> 12815875 | J13: =IF($Q13 = "Closed (Billed)",$D13,"") -> 14225621 | K13: 46031 | L13: 003.I.26 | M13: NA | N13: PO-PTEA-1125-0032 | O13: RUEGER | P13: MY | Q13: Closed (Billed) | V13: =I13 -> 12815875 | W13: 6202647.5 | X13: Spare Parts / equipment supply for existing plants | AB13: 2511010040 | AC13: =VLOOKUP(AB13,[1]Sheet3!B$2:C$78,2,0) -> 6202647.5 | AD13: =W13-AC13 -> 0
A14: Apical_ PT Asianagro Agung Jaya | B14: IDR | C14: 5000000 | D14: =MROUND((C14*1.11),1) -> 5550000 | E14: 45985 | F14: 46082 | G14: 4500446067 | H14: 46082 | I14: =IF($Q14 = "Closed (Billed)",$C14,"") -> 5000000 | J14: =IF($Q14 = "Closed (Billed)",$D14,"") -> 5550000 | K14: 46108 | L14: 003.III.26 | M14: NA | N14: PO-PTEA-1225-0035 | O14: HELS ENDUSTRIYEL | P14: TURKEY | Q14: Closed (Billed) | R14: 4879.5 | S14: USD | T14: HELS ENDUSTRIYEL | V14: =I14 -> 5000000 | W14: -7613541 | X14: Spare Parts / equipment supply for existing plants | AB14: 2512010042 | AC14: =VLOOKUP(AB14,[1]Sheet3!B$2:C$78,2,0) -> -7613541 | AD14: =W14-AC14 -> 0
A15: Apical_ PT Padang Raya Cakrawala | B15: IDR | C15: 61963200 | D15: =MROUND((C15*1.11),1) -> 68779152 | E15: 45999 | F15: 46082 | G15: 4500448557 | H15: 46082 | I15: =IF($Q15 = "Closed (Billed)",$C15,"") -> 61963200 | J15: =IF($Q15 = "Closed (Billed)",$D15,"") -> 68779152 | K15: 46097 | L15: 001.III.26 | M15: NA | N15: PO-PTEA-1225-0036 | O15: FIKE | P15: EUR | Q15: Closed (Billed) | R15: 2064.95 | S15: USD | T15: FIKE | V15: =I15 -> 61963200 | W15: 19821230 | X15: Spare Parts / equipment supply for existing plants | AB15: 2512010044 | AC15: =VLOOKUP(AB15,[1]Sheet3!B$2:C$78,2,0) -> 19821230 | AD15: =W15-AC15 -> 0
A16: PT. Sinarmas Bio Energy | B16: IDR | C16: 13500000 | D16: =MROUND((C16*1.11),1) -> 14985000 | E16: 46001 | F16: 46113 | G16: 9900037356 | H16: 46113 | I16: =IF($Q16 = "Closed (Billed)",$C16,"") -> 13500000 | J16: =IF($Q16 = "Closed (Billed)",$D16,"") -> 14985000 | K16: 46125 | L16: 003.IV.26 | M16: NA | N16: PO-PTEA-1225-0039 | O16: PT ELANG | P16: ID | Q16: Closed (Billed) | R16: 7250000 | S16: IDR | T16: PT ELANG | V16: =I16 -> 13500000 | W16: 6250000 | X16: MRO | AB16: 2512010046 | AC16: =VLOOKUP(AB16,[1]Sheet3!B$2:C$78,2,0) -> 6250000 | AD16: =W16-AC16 -> 0
A17: PT WIRASWASTA GEMILANG INDONESIA | B17: IDR | C17: 3955000000 | D17: =MROUND((C17*1.11),1) -> 4390050000 | E17: 46010 | F17: 46356 | G17: 252177 NO SAP-02 | I17: =IF($Q17 = "Closed (Billed)",$C17,"") | J17: =IF($Q17 = "Closed (Billed)",$D17,"") | M17: JN44250043 | N17: PO-PTEA-1225-0038 | O17: INGERSOLL RAND | P17: SG | Q17: Open | R17: 184210.53 | S17: EUR | T17: EXION ASIA PTE LTD | V17: =I17 | AB17: 2512010045 | AC17: =VLOOKUP(AB17,[1]Sheet3!B$2:C$78,2,0) -> -22626125 | AD17: =W17-AC17 -> 22626125
A18: ENERGI SEJAHTERA MAS | B18: IDR | C18: 119652546 | D18: =MROUND((C18*1.11),1) -> 132814326 | E18: 46003 | F18: 46113 | G18: 3100018084 | H18: 46143 | I18: =IF($Q18 = "Closed (Billed)",$C18,"") -> 119652546 | J18: =IF($Q18 = "Closed (Billed)",$D18,"") -> 132814326 | K18: 46148 | L18: 001.V.26 | M18: JN79260010 | N18: PO-PTEA-0126-0005 | O18: RITAG | P18: DE | Q18: Closed (Billed) | R18: 3336.4 | S18: EUR | T18: EXION ASIA PTE LTD | V18: =I18 -> 119652546 | W18: 40651550 | X18: Spare Parts / equipment supply for existing plants | AB18: 2512010047 | AC18: =VLOOKUP(AB18,[1]Sheet3!B$2:C$78,2,0) -> 40651550 | AD18: =W18-AC18 -> 0
A19: PT Amman Mineral Industri | B19: IDR | C19: 18937708 | D19: =MROUND((C19*1.11),1) -> 21020856 | E19: 46000 | F19: 46113 | G19: 3600003837 | H19: 46143 | I19: =IF($Q19 = "Closed (Billed)",$C19,"") -> 18937708 | J19: =IF($Q19 = "Closed (Billed)",$D19,"") -> 21020856 | K19: 46162 | L19: 005.V.26 | M19: JN82260018 | N19: PO-PTEA-0126-0001 | O19: INTERVALVE POONAWALLA PVT. LTD. | P19: INDIA | Q19: Closed (Billed) | R19: 2205 | S19: USD | T19: EXION ASIA PTE LTD | V19: =I19 -> 18937708 | W19: 4633145.5 | X19: Spare Parts / equipment supply for existing plants | AB19: 2601010001 | AC19: =VLOOKUP(AB19,[1]Sheet3!B$2:C$78,2,0) -> 4633145.5 | AD19: =W19-AC19 -> 0
A20: PLN NUSANTARA POWER SERVICES | B20: IDR | C20: 163050000 | D20: =MROUND((C20*1.11),1) -> 180985500 | E20: 46024 | F20: 46113 | G20: 005.SPK/SCM/PLN-NPS/2026 | I20: =IF($Q20 = "Closed (Billed)",$C20,"") | J20: =IF($Q20 = "Closed (Billed)",$D20,"") | M20: NA | N20: PO-PTEA-0126-0002 | O20: PT. KAKAS NURAIN FALAH | P20: ID | Q20: Open | R20: 119235375 | S20: IDR | T20: PT. KAKAS NURAIN FALAH | V20: =I20 | AB20: 2601010002 | AC20: =VLOOKUP(AB20,[1]Sheet3!B$2:C$78,2,0) -> -119235376 | AD20: =W20-AC20 -> 119235376
A21: PT. Pacrim Nusantara Lestari Foods | B21: IDR | C21: 10404786 | D21: =MROUND((C21*1.11),1) -> 11549312 | E21: 46036 | F21: 46082 | G21: 71004541 | H21: 46082 | I21: =IF($Q21 = "Closed (Billed)",$C21,"") -> 10404786 | J21: =IF($Q21 = "Closed (Billed)",$D21,"") -> 11549312 | K21: 46107 | L21: 006.III.26 | M21: NA | N21: PO-PTEA-0126-0006 | O21: ENCORD SDN BHD | P21: MY | Q21: Closed (Billed) | R21: 380 | S21: USD | T21: ENCORD SDN BHD | V21: =I21 -> 10404786 | W21: 2821225 | X21: Spare Parts / equipment supply for existing plants | AB21: 2601010003 | AC21: =VLOOKUP(AB21,[1]Sheet3!B$2:C$78,2,0) -> 2821225 | AD21: =W21-AC21 -> 0
A22: PT BHUMI JATI POWER_PO | B22: IDR | C22: 22000000 | D22: =MROUND((C22*1.11),1) -> 24420000 | E22: 46037 | F22: 46113 | G22: PO-BJP-26-1046-MMT | H22: 46174 | I22: =IF($Q22 = "Closed (Billed)",$C22,"") -> 22000000 | J22: =IF($Q22 = "Closed (Billed)",$D22,"") -> 24420000 | K22: 46188 | L22: 005.VI.26 | M22: JN79260012 | N22: PO-PTEA-0126-0007 | O22: EXION | P22: SG | Q22: Closed (Billed) | R22: 297.85 | S22: EUR | T22: EXION ASIA PTE LTD | V22: =I22 -> 22000000 | AB22: 2601010004 | AC22: =VLOOKUP(AB22,[1]Sheet3!B$2:C$78,2,0) -> -11845712 | AD22: =W22-AC22 -> 11845712
A23: PT WILMAR NABATI INDONESIA | B23: IDR | C23: 928432000 | D23: =MROUND((C23*1.11),1) -> 1030559520 | E23: 46041 | F23: 46295 | G23: 8102513355 | I23: =IF($Q23 = "Closed (Billed)",$C23,"") | J23: =IF($Q23 = "Closed (Billed)",$D23,"") | M23: JN41260012 | N23: PO-PTEA-0126-0008 | O23: VALMET | P23: CHINA/KOREA | Q23: Open | R23: 32269 | S23: EUR | T23: EXION ASIA PTE LTD | V23: =I23 | AB23: 2601010007 | AC23: =VLOOKUP(AB23,[1]Sheet3!B$2:C$78,2,0) -> -2315501 | AD23: =W23-AC23 -> 2315501
A24: PT ELMOZ GEO SOLUSI | B24: IDR | C24: 434069000 | D24: =MROUND((C24*1.11),1) -> 481816590 | E24: 46042 | F24: 46113 | G24: PO/EGS/2601/00085 | I24: =IF($Q24 = "Closed (Billed)",$C24,"") | J24: =IF($Q24 = "Closed (Billed)",$D24,"") | M24: JN01260001 | N24: PO-PTEA-0126-0003 PO-PTEA-0626-0039 PO-PTEA-0626-0040 PO-PTEA-0626-0041 PO-PTEA-0626-0042 | O24: VALVEWERKZ | P24: SG ID | Q24: Open | R24: 24,240.00 32,931,000.00 5,200,000.00 3,781,000.00 20,250,000.00 | S24: USD IDR IDR IDR IDR | T24: VALVEWERKZ PT BUDIJAYA MAKMURSENTOSA PT VALMATIC PT BUDIJAYA MAKMURSENTOSA PT RENOYAFA | V24: =I24 | AB24: 2601010005 | AC24: =VLOOKUP(AB24,[1]Sheet3!B$2:C$78,2,0) -> -2.7882511e+08 | AD24: =W24-AC24 -> 2.7882511e+08
A25: PT ELMOZ GEO SOLUSI | B25: IDR | C25: 406395000 | D25: =MROUND((C25*1.11),1) -> 451098450 | E25: 46042 | F25: 46113 | G25: PO/EGS/2601/00086 | I25: =IF($Q25 = "Closed (Billed)",$C25,"") | J25: =IF($Q25 = "Closed (Billed)",$D25,"") | M25: JN01260001 | N25: PO-PTEA-0126-0003 PO-PTEA-0626-0039 PO-PTEA-0626-0040 PO-PTEA-0626-0041 PO-PTEA-0626-0042 | O25: VALVEWERKZ | P25: SG ID | Q25: Open | R25: 24,240.00 32,931,000.00 5,200,000.00 3,781,000.00 20,250,000.00 | S25: USD IDR IDR IDR IDR | T25: VALVEWERKZ PT BUDIJAYA MAKMURSENTOSA PT VALMATIC PT BUDIJAYA MAKMURSENTOSA PT RENOYAFA | V25: =I25 | AB25: 2601010006 | AC25: =VLOOKUP(AB25,[1]Sheet3!B$2:C$78,2,0) -> -2.7882561e+08 | AD25: =W25-AC25 -> 2.7882561e+08
A26: PT WILMAR NABATI INDONESIA | B26: IDR | C26: 2807379600 | D26: =MROUND((C26*1.11),1) -> 3116191356 | E26: 46043 | F26: 46265 | G26: 8102513584 | I26: =IF($Q26 = "Closed (Billed)",$C26,"") | J26: =IF($Q26 = "Closed (Billed)",$D26,"") | M26: JN41260008 | N26: PO-PTEA-0126-0009 | O26: INTERVALVE POONAWALLA PVT. LTD. | P26: INDIA | Q26: Open | R26: 109181.1 | S26: USD | T26: EXION ASIA PTE LTD | V26: =I26 | AB26: 2601010008 | AC26: =VLOOKUP(AB26,[1]Sheet3!B$2:C$78,2,0) -> -1215350 | AD26: =W26-AC26 -> 1215350
A27: PT Asianagro Agung Jaya | B27: IDR | C27: 23800000 | D27: =MROUND((C27*1.11),1) -> 26418000 | E27: 46049 | F27: 46082 | G27: 4500456381 | H27: 46082 | I27: =IF($Q27 = "Closed (Billed)",$C27,"") -> 23800000 | J27: =IF($Q27 = "Closed (Billed)",$D27,"") -> 26418000 | K27: 46108 | L27: 004.III.26 | M27: NA | N27: PO-PTEA-1225-0035 | O27: HELS ENDUSTRIYEL | P27: TURKEY | Q27: Closed (Billed) | R27: 4879.5 | S27: USD | T27: HELS ENDUSTRIYEL | V27: =I27 -> 23800000 | W27: 6673221 | X27: Spare Parts / equipment supply for existing plants | AB27: 2601010009 | AC27: =VLOOKUP(AB27,[1]Sheet3!B$2:C$78,2,0) -> 6673221 | AD27: =W27-AC27 -> 0
A28: PT WILMAR NABATI INDONESIA | B28: IDR | C28: 87000000 | D28: =MROUND((C28*1.11),1) -> 96570000 | E28: 46063 | F28: 46265 | G28: 8102515366 | H28: 46174 | I28: =IF($Q28 = "Closed (Billed)",$C28,"") -> 87000000 | J28: =IF($Q28 = "Closed (Billed)",$D28,"") -> 96570000 | K28: 46185 | L28: 004.VI.26 | M28: JN86260037 | N28: PO-PTEA-0226-0012 | O28: PEKOS | P28: SPAIN | Q28: Closed (Billed) | R28: 3075 | S28: EUR | T28: EXION ASIA PTE LTD | V28: =I28 -> 87000000 | AB28: 2602010012 | AC28: =VLOOKUP(AB28,[1]Sheet3!B$2:C$78,2,0) -> -79419739 | AD28: =W28-AC28 -> 79419739
A29: PT. CHANDRA ASRI PACIFIC TBK. | B29: IDR | C29: 62308400 | D29: =MROUND((C29*1.11),1) -> 69162324 | E29: 46073 | F29: 46113 | G29: 4500114662 | H29: 46113 | I29: =IF($Q29 = "Closed (Billed)",$C29,"") -> 62308400 | J29: =IF($Q29 = "Closed (Billed)",$D29,"") -> 69162324 | K29: 46119 | L29: 001.IV.26 | M29: JN82260058 | N29: PO-PTEA-0226-0013 | O29: EXION | P29: SG | Q29: Closed (Billed) | R29: 3390 | S29: USD | T29: EXION ASIA PTE LTD | V29: =I29 -> 62308400 | W29: 13338955 | X29: Spare Parts / equipment supply for existing plants | AB29: 2602010011 | AC29: =VLOOKUP(AB29,[1]Sheet3!B$2:C$78,2,0) -> 13338955 | AD29: =W29-AC29 -> 0
A30: PT. CHANDRA ASRI PACIFIC TBK. | B30: IDR | C30: 94824800 | D30: =MROUND((C30*1.11),1) -> 105255528 | E30: 46073 | F30: 46202 | G30: 8600000973 | I30: =IF($Q30 = "Closed (Billed)",$C30,"") | J30: =IF($Q30 = "Closed (Billed)",$D30,"") | M30: NA | N30: PO-PTEA-0326-0014 | O30: PT MITRA WARA PRATAMA | P30: ID | Q30: Open | R30: 82000000 | S30: IDR | T30: PT MITRA WARA PRATAMA | V30: =I30 | AB30: 2602010010 | AC30: =VLOOKUP(AB30,[1]Sheet3!B$2:C$78,2,0) -> #N/A | AD30: =W30-AC30 -> #N/A
A31: PT ELMOZ GEO SOLUSI | B31: IDR | C31: 17811000 | D31: =MROUND((C31*1.11),1) -> 19770210 | E31: 46079 | F31: 46150 | G31: PO/EGS/2602/00295 | I31: =IF($Q31 = "Closed (Billed)",$C31,"") | J31: =IF($Q31 = "Closed (Billed)",$D31,"") | M31: JN01260006 | N31: PO-PTEA-0326-0018 | O31: VALVEWERKZ | P31: SG | Q31: Open | R31: 623 | S31: USD | T31: VALVEWERKZ | V31: =I31 | AB31: 2602010014 | AC31: =VLOOKUP(AB31,[1]Sheet3!B$2:C$78,2,0) -> #N/A | AD31: =W31-AC31 -> #N/A
A32: PT. SINAR MAS AGRO RESOURCES AND TECHNOLOGY TBK. (SMART TBK.) | B32: IDR | C32: 31796000 | D32: =MROUND((C32*1.11),1) -> 35293560 | E32: 46077 | F32: 46113 | G32: 9900043735 | H32: 46113 | I32: =IF($Q32 = "Closed (Billed)",$C32,"") -> 31796000 | J32: =IF($Q32 = "Closed (Billed)",$D32,"") -> 35293560 | K32: 46139 | L32: 005.IV.26 | M32: NA | N32: PO-PTEA-0326-0016 | O32: ENCORD | P32: MY | Q32: Closed (Billed) | R32: 2970 | S32: USD | T32: ENCORD SDN BHD | V32: =I32 -> 31796000 | W32: 4381657 | X32: Spare Parts / equipment supply for existing plants | AB32: 2602010013 | AC32: =VLOOKUP(AB32,[1]Sheet3!B$2:C$78,2,0) -> 4381657 | AD32: =W32-AC32 -> 0
A33: PT. KALBIO GLOBAL MEDIKA | B33: IDR | C33: 39288600 | D33: =MROUND((C33*1.11),1) -> 43610346 | E33: 46085 | F33: 46122 | G33: LPOX2603007 | H33: 46113 | I33: =IF($Q33 = "Closed (Billed)",$C33,"") -> 39288600 | J33: =IF($Q33 = "Closed (Billed)",$D33,"") -> 43610346 | K33: 46118 | L33: 004.IV.26 | M33: JN86260061 | N33: PO-PTEA-0326-0017 | O33: EXION | P33: SG | Q33: Closed (Billed) | R33: 1422 | S33: USD | T33: EXION ASIA PTE LTD | U33: PROFIT SHARING | V33: =I33 -> 39288600 | W33: 12072214 | X33: Spare Parts / equipment supply for existing plants | AB33: 2603010015 | AC33: =VLOOKUP(AB33,[1]Sheet3!B$2:C$78,2,0) -> 12072214 | AD33: =W33-AC33 -> 0
A34: PT. CHANDRA ASRI PACIFIC TBK. | B34: IDR | C34: 6358000 | D34: =MROUND((C34*1.11),1) -> 7057380 | E34: 46097 | F34: 46119 | G34: 4500115032 | H34: 46113 | I34: =IF($Q34 = "Closed (Billed)",$C34,"") -> 6358000 | J34: =IF($Q34 = "Closed (Billed)",$D34,"") -> 7057380 | K34: 46119 | L34: 002.IV.26 | M34: NA | N34: stock from PO-PTEA-0226-0013 | O34: PT EXSRI STOCK | P34: NA | Q34: Closed (Billed) | R34: NA | S34: NA | T34: NA | V34: =I34 -> 6358000 | W34: 861760 | X34: Spare Parts / equipment supply for existing plants | AB34: 2603010016 | AC34: =VLOOKUP(AB34,[1]Sheet3!B$2:C$78,2,0) -> 861760 | AD34: =W34-AC34 -> 0
A35: PT. SINAR MAS AGRO RESOURCES ANDTECHNOLOGY TBK. (SMART TBK.) | B35: IDR | C35: 20865692 | D35: =MROUND((C35*1.11),1) -> 23160918 | E35: 46107 | F35: 46219 | G35: 9900046435 | I35: =IF($Q35 = "Closed (Billed)",$C35,"") | J35: =IF($Q35 = "Closed (Billed)",$D35,"") | M35: NA | N35: PO-PTEA-0426-0021 | O35: VALVEWERKZ | P35: SG | Q35: Open | R35: 812 | S35: USD | T35: ENCORD SDN BHD | V35: =I35 | AB35: 2603010017 | AC35: =VLOOKUP(AB35,[1]Sheet3!B$2:C$78,2,0) -> -1872103 | AD35: =W35-AC35 -> 1872103
A36: PT ELMOZ GEO SOLUSI | B36: IDR | C36: 108288000 | D36: =MROUND((C36*1.11),1) -> 120199680 | E36: 46111 | F36: 46234 | G36: PO/EGS/2603/00388 | I36: =IF($Q36 = "Closed (Billed)",$C36,"") | J36: =IF($Q36 = "Closed (Billed)",$D36,"") | M36: JN01260008 | N36: PO-PTEA-0426-0022 | P36: SG | Q36: Open | R36: 3947 | S36: USD | T36: VALVEWERKZ | V36: =I36 | AB36: 2604010021 | AC36: =VLOOKUP(AB36,[1]Sheet3!B$2:C$78,2,0) -> #N/A | AD36: =W36-AC36 -> #N/A
A37: PT. CHANDRA ASRI PACIFIC TBK. | B37: IDR | C37: 114868300 | D37: =MROUND((C37*1.11),1) -> 127503813 | E37: 46114 | F37: 46177 | G37: 8600001026 | H37: 46143 | I37: =IF($Q37 = "Closed (Billed)",$C37,"") -> 114868300 | J37: =IF($Q37 = "Closed (Billed)",$D37,"") -> 127503813 | K37: 46171 | L37: 006.V.26 | M37: JN51260057 | N37: PO-PTEA-0426-0024 | P37: SG | Q37: Closed (Billed) | R37: 6688.71 | S37: SGD | T37: EXION ASIA PTE LTD | V37: =I37 -> 114868300 | W37: 25857614 | X37: Spare Parts / equipment supply for existing plants | AB37: 2604010022 | AC37: =VLOOKUP(AB37,[1]Sheet3!B$2:C$78,2,0) -> 25857614 | AD37: =W37-AC37 -> 0
A38: PT. KALBIO GLOBAL MEDIKA | B38: IDR | C38: 46494000 | D38: =MROUND((C38*1.11),1) -> 51608340 | E38: 46114 | F38: 46160 | G38: LPOX2604008 | H38: 46143 | I38: =IF($Q38 = "Closed (Billed)",$C38,"") -> 46494000 | J38: =IF($Q38 = "Closed (Billed)",$D38,"") -> 51608340 | K38: 46168 | L38: 004.V.26 | M38: JN82260099 | N38: PO-PTEA-0426-0020 | P38: SG | Q38: Closed (Billed) | R38: 1791 | S38: USD | T38: EXION ASIA PTE LTD | V38: =I38 -> 46494000 | W38: 17521738 | X38: Spare Parts / equipment supply for existing plants | AB38: 2604010018 | AC38: =VLOOKUP(AB38,[1]Sheet3!B$2:C$78,2,0) -> 17521738 | AD38: =W38-AC38 -> 0
A39: PT WILMAR NABATI INDONESIA | B39: IDR | C39: 119000000 | D39: =MROUND((C39*1.11),1) -> 132090000 | E39: 46118 | F39: 46203 | G39: 8102519410 | I39: =IF($Q39 = "Closed (Billed)",$C39,"") | J39: =IF($Q39 = "Closed (Billed)",$D39,"") | M39: JN82260101 | N39: PO-PTEA-0426-0023 | P39: SG | Q39: Open | R39: 5454 | S39: SGD | T39: EXION ASIA PTE LTD | V39: =I39 | AB39: 2604010023 | AC39: =VLOOKUP(AB39,[1]Sheet3!B$2:C$78,2,0) -> -76934592 | AD39: =W39-AC39 -> 76934592
A40: CV DUA DIGITS | B40: IDR | C40: 57681000 | D40: =MROUND((C40*1.11),1) -> 64025910 | E40: 46129 | F40: 46157 | G40: 001/PO/DD/IV/2026 | H40: 46143 | I40: =IF($Q40 = "Closed (Billed)",$C40,"") -> 57681000 | J40: =IF($Q40 = "Closed (Billed)",$D40,"") -> 64025910 | K40: 46168 | L40: 003.V.26 | M40: JN82260107 | N40: PO-PTEA-0426-0026 | P40: SG | Q40: Closed (Billed) | R40: 3042 | S40: SGD | T40: EXION ASIA PTE LTD | V40: =I40 -> 57681000 | W40: 14289525 | X40: Spare Parts / equipment supply for existing plants | AB40: 2604010019 | AC40: =VLOOKUP(AB40,[1]Sheet3!B$2:C$78,2,0) -> 14289525 | AD40: =W40-AC40 -> 0
...

Sheet QC Reporting 
H1: Checking Sales: | I1: =SUM(C9:I9)-'Backlog Checking'!O51 -> 0
H2: Checking backlog: | I2: =SUM(C8:I8)-'Backlog Checking'!O50 -> 0
C3: Indonesia -James
B4: 2025 | C4: 2026 | D4: 2026 | E4: 2026 | F4: 2026 | G4: 2026 | H4: 2026 | I4: 2026 | J4: 2026 | K4: 2026 | L4: 2026 | M4: 2026 | N4: 2026
B5: Dec | C5: Jan | D5: Feb | E5: Mar | F5: Apr | G5: May | H5: Jun | I5: Jul | J5: Aug | K5: Sep | L5: Oct | M5: Nov | N5: Dec
A6: MTD
A7: Opening balance-orderbook/backlog | B7: 1302667549 | C7: =B10 -> 5208407649 | D7: =C10 -> 9820665558 | E7: =D10 -> 10114405758 | F7: =E10 -> 9715524470 | G7: =F10 -> 18769597770 | H7: =G10 -> 19276312626 | I7: =H10 -> 18937885502 | J7: =I10 -> 18937885502 | ... N7: =M10 -> 18937885502
A8: Order intake / received - MTD | B8: 4211928870 | C8: ='Order Booking > Billing 2026'!C67 -> 4814468094 | D8: ='Order Booking > Billing 2026'!C68 -> 293740200 | E8: ='Order Booking > Billing 2026'!C69 -> 66512292 | F8: ='Order Booking > Billing 2026'!C70 -> 9355281300 | G8: ='Order Booking > Billing 2026'!C71 -> 864348410 | H8: ='Order Booking > Billing 2026'!C72 -> 309884000
A9: Sales - MTD | B9: 306188770 | C9: ='Sales-MTD'!G4 -> 202210185 | D9: ='Sales-MTD'!G5 -> 0 | E9: ='Sales-MTD'!G6 -> 465393580 | F9: ='Sales-MTD'!G7 -> 301208000 | G9: ='Sales-MTD'!G8 -> 357633554 | H9: ='Sales-MTD'!G9 -> 648311124
A10: Closing balance-orderbook/backlog | B10: =B7+B8-B9 -> 5208407649 | C10: =C7+C8-C9 -> 9820665558 | D10: =D7+D8-D9 -> 10114405758 | E10: =E7+E8-E9 -> 9715524470 | F10: =F7+F8-F9 -> 18769597770 | G10: =G7+G8-G9 -> 19276312626 | H10: =H7+H8-H9 -> 18937885502 | I10: =I7+I8-I9 -> 18937885502 | ... N10: =N7+N8-N9 -> 18937885502
A11: Checking:_ | J11: =J10-'Backlog Checking'!O57 -> 0
A12: Backlog that will be realized this year | B12: 0 | C12: =C10 -> 9820665558 | D12: =D10 -> 10114405758 | E12: =E10 -> 9715524470 | F12: =F10 -> 18769597770 | G12: =G10 -> 19276312626 | H12: =H10 -> 18937885502 | I12: =I10 -> 18937885502 | J12: =J10 -> 18937885502 | ... M12: =M10 -> 18937885502 | N12: 0
A14: YTD
A15: Opening balance-orderbook/backlog | B15: 0 | C15: =B18 -> 3905740100 | D15: =C15 -> 3905740100 | E15: =D15 -> 3905740100 | F15: =E15 -> 3905740100 | G15: =F15 -> 3905740100 | H15: =G15 -> 3905740100 | I15: =H15 -> 3905740100 | J15: =I15 -> 3905740100 | K15: =J15 -> 3905740100 | ... N15: =M15 -> 3905740100
A16: Order intake / received - YTD | B16: =B8 -> 4211928870 | C16: =C8 -> 4814468094 | D16: =D8+C16 -> 5108208294 | E16: =E8+D16 -> 5174720586 | F16: =F8+E16 -> 14530001886 | G16: =G8+F16 -> 15394350296 | H16: =H8+G16 -> 15704234296 | I16: =I8+H16 -> 15704234296 | J16: =I16+J8 -> 15704234296 | K16: =J16+K8 -> 15704234296 | L16: =K16+L8 -> 15704234296 | M16: =L16+M8 -> 15704234296 | N16: =M16+N8 -> 15704234296
A17: Sales - YTD | B17: =B9 -> 306188770 | C17: =C9 -> 202210185 | D17: =C17+D9 -> 202210185 | E17: =D17+E9 -> 667603765 | F17: =E17+F9 -> 968811765 | G17: =F17+G9 -> 1326445319 | H17: =G17+H9 -> 1974756443 | I17: =H17+I9 -> 1974756443 | J17: =I17+J9 -> 1974756443 | K17: =J17+K9 -> 1974756443 | ... N17: =M17+N9 -> 1974756443
A18: Closing balance-orderbook/backlog | B18: =B15+B16-B17 -> 3905740100 | C18: =C15+C16-C17 -> 8517998009 | D18: =D15+D16-D17 -> 8811738209 | E18: =E15+E16-E17 -> 8412856921 | F18: =F15+F16-F17 -> 17466930221 | G18: =G15+G16-G17 -> 17973645077 | H18: =H15+H16-H17 -> 17635217953 | I18: =I15+I16-I17 -> 17635217953 | ... N18: =N15+N16-N17 -> 17635217953
A20: Backlog that will be realized this year | C20: =C12 -> 9820665558 | D20: =D12 -> 10114405758 | E20: =E12 -> 9715524470 | F20: =F12 -> 18769597770 | G20: =G12 -> 19276312626 | H20: =H12 -> 18937885502 | I20: =I12 -> 18937885502 | J20: =J12 -> 18937885502 | ... N20: =N12 -> 0
G22: `
A24: No. of Orders | B24: 5 | C24: 9 | D24: 5 | E24: 3 | F24: 6 | G24: 8 | H24: 4 | O24: =SUM(C24:N24) -> 35
A25: Value of quotes | B25: 12326986019 | C25: 50886901577 | D25: 21128559700 | E25: 2576102000 | F25: 4881302000 | G25: 10546268000 | H25: 5216175776 | O25: =SUM(C25:N25) -> 95235309053
A26: No. of quotes | B26: 20 | C26: 15 | D26: 27 | E26: 19 | F26: 26 | G26: 37 | H26: 33 | O26: =SUM(C26:N26) -> 157
A30: FTE (Full time Employee) / Headcount
A31: Direct (Full time) | B31: 0 | C31: 0 | D31: 0 | E31: 0 | F31: 0
A32: Indirect | B32: 8.5 | C32: 8.5 | D32: 8 | E32: 9 | F32: 7 | G32: 7 | H32: 8
A33: Total | B33: =SUM(B31:B32) -> 8.5 | C33: =SUM(C31:C32) -> 8.5 | D33: =SUM(D31:D32) -> 8 | E33: =SUM(E31:E32) -> 9 | F33: =SUM(F31:F32) -> 7 | G33: =SUM(G31:G32) -> 7 | H33: =SUM(H31:H32) -> 8 | I33: =SUM(I31:I32) -> 0 | ... N33: =SUM(N31:N32) -> 0
D34: =D33-C33 -> -0.5 | E34: =E33-D33 -> 1 | F34: =F33-E33 -> -2 | G34: =G33-F33 -> 0 | H34: =H33-G33 -> 1 | I34: =I33-H33 -> -8 | J34: =J33-I33 -> 0 | K34: =K33-J33 -> 0 | ... N34: =N33-M33 -> 0
A36: Direct Personal cost : Salary + Variable bonus + CPF
D37: =D12 -> 10114405758 | E37: =D38 -> 10133343466
C38: QC | D38: 10133343466 | E38: =E8-D39+F38 -> 104952333 | F38: 57377749
D39: =D38-D37 -> 18937708 | E39: =E9 -> 465393580
E40: =E37+E38-E39 -> 9772902219
E41: =E12-E40 -> -57377749

Sheet Backlog Checking
I1: *Please put in the correct ORDER INTAKE .
A2: PT EXSRI | B2: MTD | F2: YTD | I2: REVISED as of Aug 2025 | J2: MTD | O2: YTD | R2: QC -YTD
C3: Ex Rate | K3: Ex Rate
B4: IDR | C4: 8.69e-05 | D4: SGD | F4: =B4 -> IDR | G4: =D4 -> SGD | J4: IDR | K4: 8e-05 | L4: SGD | O4: IDR | P4: SGD
A5: Backlog @1 Aug 2024 | B5: 0 | D5: =$B5*$C$4 -> 0 | E5: Backlog @1 Aug 2024 | F5: =B5 -> 0 | G5: =D5 -> 0 | I5: Backlog @30 Nov 2025 | J5: 1302667549 | L5: =J5*$K$4 -> 104213.4 | N5: Backlog @1 Aug 2024 | O5: =J5 -> 1302667549 | P5: =O5*$K$4 -> 104213.4
A6: Order intake | B6: 2.4244807e+08 | D6: =$B6*$C$4 -> 21068.738 | E6: Order intake | F6: =B6 -> 2.4244807e+08 | G6: =D6 -> 21068.738 | I6: Order intake | J6: 4211928870 | L6: =J6*$K$4 -> 336954.31 | N6: Order intake | O6: =J6 -> 4211928870 | P6: =O6*$K$4 -> 336954.31
A7: Sales | B7: 185070325 | D7: =$B7*$C$4 -> 16082.611 | E7: Sales | F7: =B7 -> 185070325 | G7: =D7 -> 16082.611 | I7: Sales | J7: 306188770 | L7: =J7*$K$4 -> 24495.102 | N7: Sales | O7: =J7 -> 306188770 | P7: =O7*$K$4 -> 24495.102
A8: Backlog @31 Dec 2024 | B8: =B5+B6-B7 -> 57377749 | D8: =D5+D6-D7 -> 4986.1264 | E8: Backlog @31 Dec 2024 | F8: =B8 -> 57377749 | G8: =D8 -> 4986.1264 | I8: Backlog @31 Dec 2025 | J8: =J5+J6-J7 -> 5208407649 | L8: =L5+L6-L7 -> 416672.61 | N8: Backlog @31 Dec 2024 | O8: =J8 -> 5208407649 | P8: =M8 -> 0
C10: 9e-05
A11: Backlog @1 Jan 2025 | B11: =B8 -> 57377749 | D11: =$B11*$C$10 -> 5163.9974 | E11: Backlog @1 Jan 2025 | F11: =B11 -> 57377749 | G11: =D11 -> 5163.9974 | I11: Backlog @1 Jan 2026 | J11: =J8 -> 5208407649 | L11: =J11*$K$4 -> 416672.61 | N11: Backlog @1 Jan 2025 | O11: =J11 -> 5208407649 | P11: =O11*$K$4 -> 416672.61
A12: Order intake | B12: 1933639419 | D12: =$B12*$C$10 -> 174027.55 | E12: Order intake | F12: =B12 -> 1933639419 | G12: =D12 -> 174027.55 | I12: Order intake | J12: ='Order Booking > Billing 2026'!C67 -> 4814468094 | L12: =J12*$K$4 -> 385157.45 | N12: Order intake | O12: =J12 -> 4814468094 | P12: =O12*$K$4 -> 385157.45
A13: Sales | B13: 3.0311007e+08 | D13: =$B13*$C$10 -> 27279.906 | E13: Sales | F13: =B13 -> 3.0311007e+08 | G13: =D13 -> 27279.906 | I13: Sales | J13: ='Sales-MTD'!G4 -> 202210185 | L13: =J13*$K$4 -> 16176.815 | N13: Sales | O13: =J13 -> 202210185 | P13: =O13*$K$4 -> 16176.815
A14: Backlog @31 May 2025 | B14: =B11+B12-B13 -> 1.6879071e+09 | D14: =D11+D12-D13 -> 151911.64 | E14: Backlog @31 May 2025 | F14: =B14 -> 1.6879071e+09 | G14: =G11+G12-G13 -> 151911.64 | I14: Backlog @31 Jan 2026 | J14: =J11+J12-J13 -> 9820665558 | L14: =L11+L12-L13 -> 785653.24 | N14: Backlog @31 Jan 2025 | O14: =J14 -> 9820665558 | P14: =P11+P12-P13 -> 785653.24
B15: ='Jun 2025'!C33 -> 1687907100
B16: =B14-B15 -> -0.38000011
C17: 8e-05
A18: Backlog @1 Jun 2025 | B18: =B14 -> 1.6879071e+09 | D18: =D14 -> 151911.64 | E18: =E11 -> Backlog @1 Jan 2025 | F18: =F11 -> 57377749 | G18: =G11 -> 5163.9974 | I18: Backlog @1 FEB 2026 | J18: =J14 -> 9820665558 | L18: =J18*$K$4 -> 785653.24 | N18: Backlog @1 FEB 2025 | O18: =O11 -> 5208407649 | P18: =O18*$K$4 -> 416672.61
A19: Order intake | B19: 0 | D19: =B19*C17 -> 0 | E19: =A19 -> Order intake | F19: =F12+B19 -> 1933639419 | G19: =G12+D19 -> 174027.55 | I19: Order intake | J19: ='Order Booking > Billing 2026'!C68 -> 293740200 | L19: =J19*$K$4 -> 23499.216 | N19: Order intake | O19: =O12+J19 -> 5108208294 | P19: =O19*$K$4 -> 408656.66
A20: Sales | B20: 60905500 | D20: =B20*C17 -> 4872.44 | E20: =A20 -> Sales | F20: =F13+B20 -> 3.6401557e+08 | G20: =G13+D20 -> 32152.346 | I20: Sales | J20: ='Sales-MTD'!G5 -> 0 | L20: =J20*$K$4 -> 0 | N20: Sales | O20: =O13+J20 -> 202210185 | P20: =O20*$K$4 -> 16176.815
A21: Backlog @30 Jun 2025 | B21: =B18+B19-B20 -> 1.6270016e+09 | D21: =D18+D19-D20 -> 147039.2 | E21: =A21 -> Backlog @30 Jun 2025 | F21: =F18+F19-F20 -> 1.6270016e+09 | G21: =G18+G19-G20 -> 147039.2 | I21: Backlog @28 FEB 2026 | J21: =J18+J19-J20 -> 10114405758 | L21: =L18+L19-L20 -> 809152.46 | N21: Backlog @28 FEB 2025 | O21: =O18+O19-O20 -> 10114405758 | P21: =P18+P19-P20 -> 809152.46
C23: =C17 -> 8e-05
A24: Backlog @1 Jul 2025 | B24: =B21 -> 1.6270016e+09 | D24: =D18 -> 151911.64 | E24: =E18 -> Backlog @1 Jan 2025 | F24: =F18 -> 57377749 | G24: =G18 -> 5163.9974 | I24: Backlog @1 Mar 2026 | J24: =J21 -> 10114405758 | L24: =J24*$K$4 -> 809152.46 | N24: Backlog @1 Mar 2025 | O24: =O18 -> 5208407649 | P24: =O24*$K$4 -> 416672.61
A25: Order intake | B25: ='Order Booking > Billing 2026'!#REF! -> #REF! | D25: =B25*C23 -> #REF! | E25: =A25 -> Order intake | F25: =F19+B25 -> #REF! | G25: =G19+D25 -> #REF! | I25: Order intake | J25: ='Order Booking > Billing 2026'!C69 -> 66512292 | L25: =J25*$K$4 -> 5320.9834 | N25: Order intake | O25: =O19+J25 -> 5174720586 | P25: =O25*$K$4 -> 413977.65
A26: Sales | B26: 1877340457 | D26: =B26*C23 -> 150187.24 | E26: =A26 -> Sales | F26: =F20+B26 -> 2.241356e+09 | G26: =G20+D26 -> 182339.58 | I26: Sales | J26: ='Sales-MTD'!G6 -> 465393580 | L26: =J26*$K$4 -> 37231.486 | N26: Sales | O26: =O20+J26 -> 667603765 | P26: =O26*$K$4 -> 53408.301
A27: Backlog @31 Jul 2025 | B27: =B24+B25-B26 -> #REF! | D27: =D24+D25-D26 -> #REF! | E27: =A27 -> Backlog @31 Jul 2025 | F27: =F24+F25-F26 -> #REF! | G27: =G24+G25-G26 -> #REF! | I27: Backlog @31 Mar 2026 | J27: =J24+J25-J26 -> 9715524470 | L27: =L24+L25-L26 -> 777241.96 | N27: Backlog @31 Mar 2025 | O27: =O24+O25-O26 -> 9715524470 | P27: =P24+P25-P26 -> 777241.96
B28: ='Order Booking > Billing 2026'!#REF! -> #REF! | F28: =F27-B27 -> #REF!
B29: =B27-B28 -> #REF!
C31: =C23 -> 8e-05 | I31: Backlog @1 Apr 2026 | J31: =J27 -> 9715524470 | L31: =J31*$K$4 -> 777241.96 | N31: Backlog @1 Apr 2025 | O31: =O24 -> 5208407649 | P31: =O31*$K$4 -> 416672.61
A32: Backlog @1 Jul 2025 | B32: =B24 -> 1.6270016e+09 | D32: =D26 -> 150187.24 | E32: =E26 -> Sales | F32: =F24 -> 57377749 | G32: =G24 -> 5163.9974 | I32: Order intake | J32: ='Order Booking > Billing 2026'!C70 -> 9355281300 | L32: =J32*$K$4 -> 748422.5 | N32: Order intake | O32: =O25+J32 -> 14530001886 | P32: =O32*$K$4 -> 1162400.2
A33: Order intake | D33: =B33*C31 -> 0 | E33: =A33 -> Order intake | F33: =F25+B33 -> #REF! | G33: =G25+D33 -> #REF! | I33: Sales | J33: ='Sales-MTD'!G7 -> 301208000 | L33: =J33*$K$4 -> 24096.64 | N33: Sales | O33: =O26+J33 -> 968811765 | P33: =O33*$K$4 -> 77504.941
A34: Sales | D34: =B34*C31 -> 0 | E34: =A34 -> Sales | F34: =F26+B34 -> 2.241356e+09 | G34: =G26+D34 -> 182339.58 | I34: Backlog @30 Apr 2026 | J34: =J31+J32-J33 -> 18769597770 | L34: =L31+L32-L33 -> 1501567.8 | N34: Backlog @30 Apr 2025 | O34: =O31+O32-O33 -> 18769597770 | P34: =P31+P32-P33 -> 1501567.8
A35: Backlog @31 Jul 2025 | B35: =B32+B33-B34 -> 1.6270016e+09 | D35: =D32+D33-D34 -> 150187.24 | E35: =A35 -> Backlog @31 Jul 2025 | F35: =F32+F33-F34 -> #REF! | G35: =G32+G33-G34 -> #REF!
F36: =F35-B35 -> #REF!
I37: Backlog @1 May 2026 | J37: =J34 -> 18769597770 | L37: =J37*$K$4 -> 1501567.8 | N37: Backlog @1 May 2025 | O37: =O31 -> 5208407649 | P37: =O37*$K$4 -> 416672.61
I38: Order intake | J38: ='Order Booking > Billing 2026'!C71 -> 864348410 | L38: =J38*$K$4 -> 69147.873 | N38: Order intake | O38: =O32+J38 -> 15394350296 | P38: =O38*$K$4 -> 1231548
I39: Sales | J39: ='Sales-MTD'!G8 -> 357633554 | L39: =J39*$K$4 -> 28610.684 | N39: Sales | O39: =O33+J39 -> 1326445319 | P39: =O39*$K$4 -> 106115.63
I40: Backlog @31 May 2026 | J40: =J37+J38-J39 -> 19276312626 | L40: =L37+L38-L39 -> 1542105 | N40: Backlog @31 May 2025 | O40: =O37+O38-O39 -> 19276312626 | P40: =P37+P38-P39 -> 1542105
I43: Backlog @1 Jun 2026 | J43: =J40 -> 19276312626 | L43: =J43*$K$4 -> 1542105 | N43: Backlog @1 Jun 2025 | O43: =O37 -> 5208407649 | P43: =O43*$K$4 -> 416672.61
I44: Order intake | J44: ='Order Booking > Billing 2026'!C72 -> 309884000 | L44: =J44*$K$4 -> 24790.72 | N44: Order intake | O44: =O38+J44 -> 15704234296 | P44: =O44*$K$4 -> 1256338.7
I45: Sales | J45: ='Sales-MTD'!G9 -> 648311124 | L45: =J45*$K$4 -> 51864.89 | N45: Sales | O45: =O39+J45 -> 1974756443 | P45: =O45*$K$4 -> 157980.52
...

Sheet Sales-MTD
A1: Status as of 19 Aug 25 ; by Nicole Soong | D1: Billed Orders | E1: =E2-INV!#REF! -> #REF!
D2: (amount excluding tax ) | E2: =SUBTOTAL(9,E4:E15) -> 1974756443 | F2: =SUBTOTAL(9,F4:F15) -> 0 | G2: =SUBTOTAL(9,G4:G15) -> 1974756443 | H2: =SUBTOTAL(9,H4:H15) -> 1974756443 | I2: =SUBTOTAL(9,I4:I15) -> 0
D3: MTH/YEAR | E3: INDONOSIA (JUL25;COLUMN H) | F3: SINGAPORE | G3: TOTAL | H3: QC Reporting Figure | I3: VARINACE
D4: 46023 | E4: =INV!H9 -> 202210185 | F4: 0 | G4: =SUM(E4:F4) -> 202210185 | H4: ='QC Reporting '!C9 -> 202210185 | I4: =H4-G4 -> 0
D5: 46054 | E5: =INV!H11 -> 0 | F5: 0 | G5: =SUM(E5:F5) -> 0 | H5: ='QC Reporting '!D9 -> 0 | I5: =H5-G5 -> 0
D6: 46082 | E6: =INV!H18 -> 465393580 | F6: 0 | G6: =SUM(E6:F6) -> 465393580 | H6: ='QC Reporting '!E9 -> 465393580 | I6: =H6-G6 -> 0
D7: 46113 | E7: =INV!H25 -> 301208000 | F7: 0 | G7: =SUM(E7:F7) -> 301208000 | H7: ='QC Reporting '!F9 -> 301208000 | I7: =H7-G7 -> 0
D8: 46143 | E8: =INV!H32 -> 357633554 | F8: 0 | G8: =SUM(E8:F8) -> 357633554 | H8: ='QC Reporting '!G9 -> 357633554 | I8: =H8-G8 -> 0
D9: 46174 | E9: =INV!H40 -> 648311124 | F9: 0 | G9: =SUM(E9:F9) -> 648311124 | H9: ='QC Reporting '!H9 -> 648311124 | I9: =H9-G9 -> 0
D10: 46204 | E10: 0 | F10: 0 | G10: =SUM(E10:F10) -> 0 | H10: 0 | I10: =H10-G10 -> 0
D11: 46235 | E11: 0 | F11: 0 | G11: =SUM(E11:F11) -> 0 | H11: 0 | I11: =H11-G11 -> 0
D12: 46266 | E12: 0 | F12: 0 | G12: =SUM(E12:F12) -> 0 | H12: 0 | I12: =H12-G12 -> 0
D13: 46296 | E13: 0 | F13: 0 | G13: =SUM(E13:F13) -> 0 | H13: 0 | I13: =H13-G13 -> 0
D14: 46327 | E14: 0 | F14: 0 | G14: =SUM(E14:F14) -> 0 | H14: 0 | I14: =H14-G14 -> 0
D15: 46357 | E15: 0 | F15: 0 | G15: =SUM(E15:F15) -> 0 | I15: =H15-G15 -> 0

Sheet INV
B2: PT EXION SOLUSI REKAYASA INDONESIA
B3: SALES 2026
J4: 4-0031
B5: INVOICE | C5: TGL INVOICE | D5: FAKTUR | E5: JOB NO | F5: PO NO | G5: CUSTOMER | H5: GROSS AMT | I5: VAT 11% | J5: NET TOTAL
B6: 001.I.26 | C6: 46029 | D6: 04002600007115437 | E6: 251101037 | F6: 2794/11/2025/MEI66 REVISI-1 | G6: OSA PUTRA ENGINEERING,PT PEL 50% | H6: 108274310 | I6: =MROUND((K6*11%),1) -> 5955087 | J6: =K6+I6 -> 60092242 | K6: 54137155
B7: 002.I.26 | C7: 46030 | D7: 04002600019448891 | E7: 251101036 | F7: 9900033981 | G7: SINAR MAS AGRO RESOURCES AND TECHNOLOGY TBK,PT | H7: 81120000 | I7: =MROUND((H7*11%),1) -> 8923200 | J7: =H7+I7 -> 90043200
B8: 003.I.26 | C8: 46031 | D8: 0400460019549402 | E8: 251101040 | F8: 4710193706-ID1/1120 | G8: EVONIK INDONESIA | H8: 12815875 | I8: =MROUND((H8*11%),1) -> 1409746 | J8: =H8+I8 -> 14225621
B9: TOTAL JAN'26 | H9: =SUM(H6:H8) -> 202210185 | I9: =SUM(I6:I8) -> 16288033 | J9: =SUM(J6:J8) -> 164361063
